Workbook

Sheet Authorization Required

Sheet directory
A1: id_no | B1: =IFERROR(__xludf.DUMMYFUNCTION("query(Data!A:AD,""Select U, B, C, D, E, F, G, H, AB, AC, J, K, L, M, N, O, P, R, S, T, V, W, X, Y, Z, AA, AD Order by B, K"")"),"client_zip_codes") -> client_zip_codes | C1: =IFERROR(__xludf.DUMMYFUNCTION("""COMPUTED_VALUE"""),"organization") -> organization | D1: =IFERROR(__xludf.DUMMYFUNCTION("""COMPUTED_VALUE"""),"org_address1") -> org_address1 | E1: =IFERROR(__xludf.DUMMYFUNCTION("""COMPUTED_VALUE"""),"org_address2") -> org_address2 | F1: =IFERROR(__xludf.DUMMYFUNCTION("""COMPUTED_VALUE"""),"org_city") -> org_city | G1: =IFERROR(__xludf.DUMMYFUNCTION("""COMPUTED_VALUE"""),"org_state") -> org_state | H1: =IFERROR(__xludf.DUMMYFUNCTION("""COMPUTED_VALUE"""),"org_zip_code") -> org_zip_code | I1: =IFERROR(__xludf.DUMMYFUNCTION("""COMPUTED_VALUE"""),"org_telephone") -> org_telephone | J1: =IFERROR(__xludf.DUMMYFUNCTION("""COMPUTED_VALUE"""),"org_coordinates") -> org_coordinates | K1: =IFERROR(__xludf.DUMMYFUNCTION("""COMPUTED_VALUE"""),"org_hours") -> org_hours | L1: =IFERROR(__xludf.DUMMYFUNCTION("""COMPUTED_VALUE"""),"hours_notes") -> hours_notes | M1: =IFERROR(__xludf.DUMMYFUNCTION("""COMPUTED_VALUE"""),"assist_id") -> assist_id | N1: =IFERROR(__xludf.DUMMYFUNCTION("""COMPUTED_VALUE"""),"assistance") -> assistance | O1: =IFERROR(__xludf.DUMMYFUNCTION("""COMPUTED_VALUE"""),"status_id") -> status_id | P1: =IFERROR(__xludf.DUMMYFUNCTION("""COMPUTED_VALUE"""),"status") -> status | Q1: =IFERROR(__xludf.DUMMYFUNCTION("""COMPUTED_VALUE"""),"status_date") -> status_date | R1: =IFERROR(__xludf.DUMMYFUNCTION("""COMPUTED_VALUE"""),"status_text") -> status_text | S1: =IFERROR(__xludf.DUMMYFUNCTION("""COMPUTED_VALUE"""),"requirements") -> requirements | T1: =IFERROR(__xludf.DUMMYFUNCTION("""COMPUTED_VALUE"""),"is_first_bold") -> is_first_bold | U1: =IFERROR(__xludf.DUMMYFUNCTION("""COMPUTED_VALUE"""),"is_first_red") -> is_first_red | V1: =IFERROR(__xludf.DUMMYFUNCTION("""COMPUTED_VALUE"""),"webpage") -> webpage | W1: =IFERROR(__xludf.DUMMYFUNCTION("""COMPUTED_VALUE"""),"googlemaps") -> googlemaps | X1: =IFERROR(__xludf.DUMMYFUNCTION("""COMPUTED_VALUE"""),"org_email") -> org_email | Y1: =IFERROR(__xludf.DUMMYFUNCTION("""COMPUTED_VALUE"""),"org_county") -> org_county | Z1: =IFERROR(__xludf.DUMMYFUNCTION("""COMPUTED_VALUE"""),"zip_neighborhoods") -> zip_neighborhoods | AA1: =IFERROR(__xludf.DUMMYFUNCTION("""COMPUTED_VALUE"""),"org_parent") -> org_parent | AB1: =IFERROR(__xludf.DUMMYFUNCTION("""COMPUTED_VALUE"""),"org_neighborhood") -> org_neighborhood
A2: {=IF(ISBLANK(B2:B1999), "", ROW(B2:B1999)-1)} -> 1 | B2: =IFERROR(__xludf.DUMMYFUNCTION("""COMPUTED_VALUE"""),"[""77002"", ""77003"", ""77004"", ""77005"", ""77006"", ""77007"", ""77008"", ""77009"", ""77010"", ""77011"", ""77012"", ""77013"", ""77014"", ""77015"", ""77016"", ""77017"", ""77018"", ""77019"", ""77020"", ""77021"", ""77022"", ""77023"", ""77024"", "&"""77025"", ""77026"", ""77027"", ""77028"", ""77029"", ""77030"", ""77031"", ""77032"", ""77033"", ""77034"", ""77035"", ""77036"", ""77037"", ""77038"", ""77039"", ""77040"", ""77041"", ""77042"", ""77043"", ""77044"", ""77045"", ""77046"", ""77047"", """&"77048"", ""77049"", ""77050"", ""77051"", ""77053"", ""77054"", ""77055"", ""77056"", ""77057"", ""77058"", ""77059"", ""77060"", ""77061"", ""77062"", ""77063"", ""77064"", ""77065"", ""77066"", ""77067"", ""77068"", ""77069"", ""77070"", ""77071"", ""77"&"072"", ""77073"", ""77074"", ""77075"", ""77076"", ""77077"", ""77078"", ""77079"", ""77080"", ""77081"", ""77082"", ""77083"", ""77084"", ""77085"", ""77086"", ""77087"", ""77088"", ""77089"", ""77090"", ""77091"", ""77092"", ""77093"", ""77094"", ""7709"&"5"", ""77096"", ""77098"", ""77099"", ""77242"", ""77257"", ""77277"", ""77279"", ""77336"", ""77338"", ""77339"", ""77345"", ""77346"", ""77347"", ""77357"", ""77365"", ""77373"", ""77375"", ""77377"", ""77379"", ""77383"", ""77387"", ""77388"", ""77389"&""", ""77393"", ""77396"", ""77401"", ""77406"", ""77407"", ""77410"", ""77417"", ""77423"", ""77429"", ""77430"", ""77433"", ""77441"", ""77444"", ""77447"", ""77449"", ""77450"", ""77451"", ""77459"", ""77461"", ""77464"", ""77469"", ""77471"", ""77476"""&", ""77477"", ""77478"", ""77479"", ""77481"", ""77484"", ""77485"", ""77489"", ""77493"", ""77494"", ""77498"", ""77501"", ""77502"", ""77503"", ""77504"", ""77505"", ""77506"", ""77507"", ""77508"", ""77520"", ""77521"", ""77530"", ""77532"", ""77535"", "&"""77536"", ""77545"", ""77546"", ""77547"", ""77562"", ""77571"", ""77581"", ""77583"", ""77584"", ""77586"", ""77587"", ""77598""]") -> ["77002", "77003", "77004", "77005", "77006", "77007", "77008", "77009", "77010", "77011", "77012", "77013", "77014", "77015", "77016", "77017", "77018", "77019", "77020", "77021", "77022", "77023", "77024", "77025", "77026", "77027", "77028", "77029", "77030", "77031", "77032", "77033", "77034", "77035", "77036", "77037", "77038", "77039", "77040", "77041", "77042", "77043", "77044", "77045", "77046", "77047", "77048", "77049", "77050", "77051", "77053", "77054", "77055", "77056", "77057", "77058", "77059", "77060", "77061", "77062", "77063", "77064", "77065", "77066", "77067", "77068", "77069", "77070", "77071", "77072", "77073", "77074", "77075", "77076", "77077", "77078", "77079", "77080", "77081", "77082", "77083", "77084", "77085", "77086", "77087", "77088", "77089", "77090", "77091", "77092", "77093", "77094", "77095", "77096", "77098", "77099", "77242", "77257", "77277", "77279", "77336", "77338", "77339", "77345", "77346", "77347", "77357", "77365", "77373", "77375", "77377", "77379", "77383", "77387", "77388", "77389", "77393", "77396", "77401", "77406", "77407", "77410", "77417", "77423", "77429", "77430", "77433", "77441", "77444", "77447", "77449", "77450", "77451", "77459", "77461", "77464", "77469", "77471", "77476", "77477", "77478", "77479", "77481", "77484", "77485", "77489", "77493", "77494", "77498", "77501", "77502", "77503", "77504", "77505", "77506", "77507", "77508", "77520", "77521", "77530", "77532", "77535", "77536", "77545", "77546", "77547", "77562", "77571", "77581", "77583", "77584", "77586", "77587", "77598"] | C2: =IFERROR(__xludf.DUMMYFUNCTION("""COMPUTED_VALUE"""),"3 ""A"" Bereavement Foundation (3ABF)") -> 3 "A" Bereavement Foundation (3ABF) | D2: =IFERROR(__xludf.DUMMYFUNCTION("""COMPUTED_VALUE"""),"5330 Griggs Road") -> 5330 Griggs Road | E2: =IFERROR(__xludf.DUMMYFUNCTION("""COMPUTED_VALUE"""),"Suite A108") -> Suite A108 | F2: =IFERROR(__xludf.DUMMYFUNCTION("""COMPUTED_VALUE"""),"Houston") -> Houston | G2: =IFERROR(__xludf.DUMMYFUNCTION("""COMPUTED_VALUE"""),"TX") -> TX | H2: =IFERROR(__xludf.DUMMYFUNCTION("""COMPUTED_VALUE"""),"77021") -> 77021 | I2: =IFERROR(__xludf.DUMMYFUNCTION("""COMPUTED_VALUE"""),"713-649-3232") -> 713-649-3232 | J2: =IFERROR(__xludf.DUMMYFUNCTION("""COMPUTED_VALUE"""),"29.6967871212121, -95.3336860909091") -> 29.6967871212121, -95.3336860909091 | K2: =IFERROR(__xludf.DUMMYFUNCTION("""COMPUTED_VALUE"""),"{""regular"":[{""days"":[""Mo"",""Tu"",""We"",""Th"",""Fr""],""open"":""09:00"",""close"":""17:00""}]}") -> {"regular":[{"days":["Mo","Tu","We","Th","Fr"],"open":"09:00","close":"17:00"}]} | M2: =IFERROR(__xludf.DUMMYFUNCTION("""COMPUTED_VALUE"""),65.0) -> 65 | N2: =IFERROR(__xludf.DUMMYFUNCTION("""COMPUTED_VALUE"""),"Other") -> Other | O2: =IFERROR(__xludf.DUMMYFUNCTION("""COMPUTED_VALUE"""),1.0) -> 1 | P2: =IFERROR(__xludf.DUMMYFUNCTION("""COMPUTED_VALUE"""),"ACTIVE") -> ACTIVE | Q2: =IFERROR(__xludf.DUMMYFUNCTION("""COMPUTED_VALUE"""),45789.0) -> 45789 | R2: =IFERROR(__xludf.DUMMYFUNCTION("""COMPUTED_VALUE"""),"Verified online") -> Verified online | S2: =IFERROR(__xludf.DUMMYFUNCTION("""COMPUTED_VALUE"""),"Financial assistance for funeral services. Needs based. Financial verification required. Funeral consultations. Grief counseling. Aftercare services") -> Financial assistance for funeral services. Needs based. Financial verification required. Funeral consultations. Grief counseling. Aftercare services | T2: =IFERROR(__xludf.DUMMYFUNCTION("""COMPUTED_VALUE"""),FALSE) -> FALSE | U2: =IFERROR(__xludf.DUMMYFUNCTION("""COMPUTED_VALUE"""),FALSE) -> FALSE | V2: =IFERROR(__xludf.DUMMYFUNCTION("""COMPUTED_VALUE"""),"https://3abereavement.weebly.com/") -> https://3abereavement.weebly.com/ | W2: =IFERROR(__xludf.DUMMYFUNCTION("""COMPUTED_VALUE"""),"https://www.google.com/maps/place/Three+A+Bereavement/@29.6962313,-95.3378945,16z/data=!3m1!4b1!4m6!3m5!1s0x8640be3dadb801b5:0x44b0b287f8f22ef6!8m2!3d29.6962267!4d-95.3353142!16s%2Fg%2F1tlqqcg1?entry=ttu&g_ep=EgoyMDI1MDUwNy4wIKXMDSoASAFQAw%3D%3D") -> https://www.google.com/maps/place/Three+A+Bereavement/@29.6962313,-95.3378945,16z/data=!3m1!4b1!4m6!3m5!1s0x8640be3dadb801b5:0x44b0b287f8f22ef6!8m2!3d29.6962267!4d-95.3353142!16s%2Fg%2F1tlqqcg1?entry=ttu&g_ep=EgoyMDI1MDUwNy4wIKXMDSoASAFQAw%3D%3D | Y2: =IFERROR(__xludf.DUMMYFUNCTION("""COMPUTED_VALUE"""),"Houston") -> Houston | Z2: =IFERROR(__xludf.DUMMYFUNCTION("""COMPUTED_VALUE"""),"MacGregor, Riverside Terrace, South Side") -> MacGregor, Riverside Terrace, South Side | AA2: =IFERROR(__xludf.DUMMYFUNCTION("""COMPUTED_VALUE"""),"3 ""A"" Bereavement Foundation (3ABF)") -> 3 "A" Bereavement Foundation (3ABF) | AB2: =IFERROR(__xludf.DUMMYFUNCTION("""COMPUTED_VALUE"""),"South Side") -> South Side
A3: 2 | B3: =IFERROR(__xludf.DUMMYFUNCTION("""COMPUTED_VALUE"""),"[""99999""]") -> ["99999"] | C3: =IFERROR(__xludf.DUMMYFUNCTION("""COMPUTED_VALUE"""),"A Touch of God's Love Outreach") -> A Touch of God's Love Outreach | D3: =IFERROR(__xludf.DUMMYFUNCTION("""COMPUTED_VALUE"""),"10103 Fondren Road") -> 10103 Fondren Road | E3: =IFERROR(__xludf.DUMMYFUNCTION("""COMPUTED_VALUE"""),"Suit 420") -> Suit 420 | F3: =IFERROR(__xludf.DUMMYFUNCTION("""COMPUTED_VALUE"""),"Houston") -> Houston | G3: =IFERROR(__xludf.DUMMYFUNCTION("""COMPUTED_VALUE"""),"TX") -> TX | H3: =IFERROR(__xludf.DUMMYFUNCTION("""COMPUTED_VALUE"""),"77096") -> 77096 | I3: =IFERROR(__xludf.DUMMYFUNCTION("""COMPUTED_VALUE"""),"346-701-8094") -> 346-701-8094 | J3: =IFERROR(__xludf.DUMMYFUNCTION("""COMPUTED_VALUE"""),"29.669937, -95.508457") -> 29.669937, -95.508457 | M3: =IFERROR(__xludf.DUMMYFUNCTION("""COMPUTED_VALUE"""),56.0) -> 56 | N3: =IFERROR(__xludf.DUMMYFUNCTION("""COMPUTED_VALUE"""),"Veterans") -> Veterans | O3: =IFERROR(__xludf.DUMMYFUNCTION("""COMPUTED_VALUE"""),4.0) -> 4 | P3: =IFERROR(__xludf.DUMMYFUNCTION("""COMPUTED_VALUE"""),"CLOSED") -> CLOSED | Q3: =IFERROR(__xludf.DUMMYFUNCTION("""COMPUTED_VALUE"""),45670.0) -> 45670 | R3: =IFERROR(__xludf.DUMMYFUNCTION("""COMPUTED_VALUE"""),"Phone disconnected") -> Phone disconnected | S3: =IFERROR(__xludf.DUMMYFUNCTION("""COMPUTED_VALUE"""),"Financial assistance with utilities, food, Medical - Primary Care and Handyman for Veterans, Senior Citizens and Disabled") -> Financial assistance with utilities, food, Medical - Primary Care and Handyman for Veterans, Senior Citizens and Disabled | T3: =IFERROR(__xludf.DUMMYFUNCTION("""COMPUTED_VALUE"""),FALSE) -> FALSE | U3: =IFERROR(__xludf.DUMMYFUNCTION("""COMPUTED_VALUE"""),FALSE) -> FALSE | W3: =IFERROR(__xludf.DUMMYFUNCTION("""COMPUTED_VALUE"""),"https://maps.google.com/?q=A%20Touch%20of%20God's%20Love%20Outreach%2010103%20Fondren%20Suite%20420%20Houston%20TX%2077096") -> https://maps.google.com/?q=A%20Touch%20of%20God's%20Love%20Outreach%2010103%20Fondren%20Suite%20420%20Houston%20TX%2077096 | Y3: =IFERROR(__xludf.DUMMYFUNCTION("""COMPUTED_VALUE"""),"Houston") -> Houston | Z3: =IFERROR(__xludf.DUMMYFUNCTION("""COMPUTED_VALUE"""),"Brays Oaks, Meyerland, Westbury, Willow Meadows") -> Brays Oaks, Meyerland, Westbury, Willow Meadows | AA3: =IFERROR(__xludf.DUMMYFUNCTION("""COMPUTED_VALUE"""),"A Touch of God's Love Outreach") -> A Touch of God's Love Outreach | AB3: =IFERROR(__xludf.DUMMYFUNCTION("""COMPUTED_VALUE"""),"Brays Oaks") -> Brays Oaks
A4: 3 | B4: =IFERROR(__xludf.DUMMYFUNCTION("""COMPUTED_VALUE"""),"[""99999""]") -> ["99999"] | C4: =IFERROR(__xludf.DUMMYFUNCTION("""COMPUTED_VALUE"""),"AAMA George L Sanchez Charter School North") -> AAMA George L Sanchez Charter School North | D4: =IFERROR(__xludf.DUMMYFUNCTION("""COMPUTED_VALUE"""),"170 Rittenhouse Street") -> 170 Rittenhouse Street | F4: =IFERROR(__xludf.DUMMYFUNCTION("""COMPUTED_VALUE"""),"Houston") -> Houston | G4: =IFERROR(__xludf.DUMMYFUNCTION("""COMPUTED_VALUE"""),"TX") -> TX | H4: =IFERROR(__xludf.DUMMYFUNCTION("""COMPUTED_VALUE"""),"77076") -> 77076 | I4: =IFERROR(__xludf.DUMMYFUNCTION("""COMPUTED_VALUE"""),"832-622-0685") -> 832-622-0685 | J4: =IFERROR(__xludf.DUMMYFUNCTION("""COMPUTED_VALUE"""),"29.863906955714647, -95.37843356123234") -> 29.863906955714647, -95.37843356123234 | K4: =IFERROR(__xludf.DUMMYFUNCTION("""COMPUTED_VALUE"""),"{""regular"":[{""days"":[""Mo"",""Tu"",""We"",""Th"",""Fr""],""open"":null,""close"":null}]}") -> {"regular":[{"days":["Mo","Tu","We","Th","Fr"],"open":null,"close":null}]} | M4: =IFERROR(__xludf.DUMMYFUNCTION("""COMPUTED_VALUE"""),43.0) -> 43 | N4: =IFERROR(__xludf.DUMMYFUNCTION("""COMPUTED_VALUE"""),"Education - Children") -> Education - Children | O4: =IFERROR(__xludf.DUMMYFUNCTION("""COMPUTED_VALUE"""),1.0) -> 1 | P4: =IFERROR(__xludf.DUMMYFUNCTION("""COMPUTED_VALUE"""),"ACTIVE") -> ACTIVE | Q4: =IFERROR(__xludf.DUMMYFUNCTION("""COMPUTED_VALUE"""),45893.0) -> 45893 | S4: =IFERROR(__xludf.DUMMYFUNCTION("""COMPUTED_VALUE"""),"Middle thru High School. Free Tuition which includes free breakfast and lunch. Apply online") -> Middle thru High School. Free Tuition which includes free breakfast and lunch. Apply online | T4: =IFERROR(__xludf.DUMMYFUNCTION("""COMPUTED_VALUE"""),FALSE) -> FALSE | U4: =IFERROR(__xludf.DUMMYFUNCTION("""COMPUTED_VALUE"""),FALSE) -> FALSE | V4: =IFERROR(__xludf.DUMMYFUNCTION("""COMPUTED_VALUE"""),"https://www.aama.org/apps/pages/george-i-sanchez-charter-schools") -> https://www.aama.org/apps/pages/george-i-sanchez-charter-schools | W4: =IFERROR(__xludf.DUMMYFUNCTION("""COMPUTED_VALUE"""),"https://www.google.com/maps/place/Sanchez+Charter+Middle+and+High+School/@29.8635627,-95.3810943,16z/data=!3m1!4b1!4m6!3m5!1s0x8640b80004692007:0x8f00566854f63014!8m2!3d29.8635581!4d-95.3785194!16s%2Fg%2F11c600mkxz?entry=ttu&g_ep=EgoyMDI1MDgxOS4wIKXMDSoAS"&"AFQAw%3D%3D") -> https://www.google.com/maps/place/Sanchez+Charter+Middle+and+High+School/@29.8635627,-95.3810943,16z/data=!3m1!4b1!4m6!3m5!1s0x8640b80004692007:0x8f00566854f63014!8m2!3d29.8635581!4d-95.3785194!16s%2Fg%2F11c600mkxz?entry=ttu&g_ep=EgoyMDI1MDgxOS4wIKXMDSoASAFQAw%3D%3D | Y4: =IFERROR(__xludf.DUMMYFUNCTION("""COMPUTED_VALUE"""),"Houston") -> Houston | Z4: =IFERROR(__xludf.DUMMYFUNCTION("""COMPUTED_VALUE"""),"Independence Heights, Northline, Northside / Northline") -> Independence Heights, Northline, Northside / Northline | AA4: =IFERROR(__xludf.DUMMYFUNCTION("""COMPUTED_VALUE"""),"Association for Advancement of Mexican Americans (AAMA)") -> Association for Advancement of Mexican Americans (AAMA) | AB4: =IFERROR(__xludf.DUMMYFUNCTION("""COMPUTED_VALUE"""),"Northside / Northline") -> Northside / Northline
A5: 4 | B5: =IFERROR(__xludf.DUMMYFUNCTION("""COMPUTED_VALUE"""),"[""99999""]") -> ["99999"] | C5: =IFERROR(__xludf.DUMMYFUNCTION("""COMPUTED_VALUE"""),"AAMA George L Sanchez Charter School South") -> AAMA George L Sanchez Charter School South | D5: =IFERROR(__xludf.DUMMYFUNCTION("""COMPUTED_VALUE"""),"6001 Gulf Fwy") -> 6001 Gulf Fwy | F5: =IFERROR(__xludf.DUMMYFUNCTION("""COMPUTED_VALUE"""),"Houston") -> Houston | G5: =IFERROR(__xludf.DUMMYFUNCTION("""COMPUTED_VALUE"""),"TX") -> TX | H5: =IFERROR(__xludf.DUMMYFUNCTION("""COMPUTED_VALUE"""),"77023") -> 77023 | I5: =IFERROR(__xludf.DUMMYFUNCTION("""COMPUTED_VALUE"""),"832-622-0685") -> 832-622-0685 | J5: =IFERROR(__xludf.DUMMYFUNCTION("""COMPUTED_VALUE"""),"29.714369469154935, -95.3121463531626") -> 29.714369469154935, -95.3121463531626 | K5: =IFERROR(__xludf.DUMMYFUNCTION("""COMPUTED_VALUE"""),"{""regular"":[{""days"":[""Mo"",""Tu"",""We"",""Th"",""Fr""],""open"":null,""close"":null}]}") -> {"regular":[{"days":["Mo","Tu","We","Th","Fr"],"open":null,"close":null}]} | M5: =IFERROR(__xludf.DUMMYFUNCTION("""COMPUTED_VALUE"""),43.0) -> 43 | N5: =IFERROR(__xludf.DUMMYFUNCTION("""COMPUTED_VALUE"""),"Education - Children") -> Education - Children | O5: =IFERROR(__xludf.DUMMYFUNCTION("""COMPUTED_VALUE"""),1.0) -> 1 | P5: =IFERROR(__xludf.DUMMYFUNCTION("""COMPUTED_VALUE"""),"ACTIVE") -> ACTIVE | Q5: =IFERROR(__xludf.DUMMYFUNCTION("""COMPUTED_VALUE"""),45893.0) -> 45893 | S5: =IFERROR(__xludf.DUMMYFUNCTION("""COMPUTED_VALUE"""),"Elementary thru High School. Free Tuition which includes free breakfast and lunch. Apply online") -> Elementary thru High School. Free Tuition which includes free breakfast and lunch. Apply online | T5: =IFERROR(__xludf.DUMMYFUNCTION("""COMPUTED_VALUE"""),FALSE) -> FALSE | U5: =IFERROR(__xludf.DUMMYFUNCTION("""COMPUTED_VALUE"""),FALSE) -> FALSE | V5: =IFERROR(__xludf.DUMMYFUNCTION("""COMPUTED_VALUE"""),"https://www.aama.org/apps/pages/george-i-sanchez-charter-schools") -> https://www.aama.org/apps/pages/george-i-sanchez-charter-schools | W5: =IFERROR(__xludf.DUMMYFUNCTION("""COMPUTED_VALUE"""),"https://www.google.com/maps/place/AAMA/@29.7143334,-95.3127981,19z/data=!3m1!4b1!4m6!3m5!1s0x8640bfd5e8dcfca9:0x894a10d39493d560!8m2!3d29.7143322!4d-95.3121544!16s%2Fg%2F11sszckmnd?entry=ttu&g_ep=EgoyMDI1MDgxOS4wIKXMDSoASAFQAw%3D%3D") -> https://www.google.com/maps/place/AAMA/@29.7143334,-95.3127981,19z/data=!3m1!4b1!4m6!3m5!1s0x8640bfd5e8dcfca9:0x894a10d39493d560!8m2!3d29.7143322!4d-95.3121544!16s%2Fg%2F11sszckmnd?entry=ttu&g_ep=EgoyMDI1MDgxOS4wIKXMDSoASAFQAw%3D%3D | Y5: =IFERROR(__xludf.DUMMYFUNCTION("""COMPUTED_VALUE"""),"Houston") -> Houston | Z5: =IFERROR(__xludf.DUMMYFUNCTION("""COMPUTED_VALUE"""),"Eastwood, Gulfgate Riverview / Pine Valley, Idylwood, Lawndale / Wayside, Magnolia Park, South Central Houston") -> Eastwood, Gulfgate Riverview / Pine Valley, Idylwood, Lawndale / Wayside, Magnolia Park, South Central Houston | AA5: =IFERROR(__xludf.DUMMYFUNCTION("""COMPUTED_VALUE"""),"Association for Advancement of Mexican Americans (AAMA)") -> Association for Advancement of Mexican Americans (AAMA) | AB5: =IFERROR(__xludf.DUMMYFUNCTION("""COMPUTED_VALUE"""),"Lawndale / Wayside") -> Lawndale / Wayside
A6: 5 | B6: =IFERROR(__xludf.DUMMYFUNCTION("""COMPUTED_VALUE"""),"[""99999""]") -> ["99999"] | C6: =IFERROR(__xludf.DUMMYFUNCTION("""COMPUTED_VALUE"""),"Ability Found") -> Ability Found | D6: =IFERROR(__xludf.DUMMYFUNCTION("""COMPUTED_VALUE"""),"2324 S Constitution Blvd") -> 2324 S Constitution Blvd | F6: =IFERROR(__xludf.DUMMYFUNCTION("""COMPUTED_VALUE"""),"West Valley City") -> West Valley City | G6: =IFERROR(__xludf.DUMMYFUNCTION("""COMPUTED_VALUE"""),"UT") -> UT | H6: =IFERROR(__xludf.DUMMYFUNCTION("""COMPUTED_VALUE"""),"84119") -> 84119 | I6: =IFERROR(__xludf.DUMMYFUNCTION("""COMPUTED_VALUE"""),"801-505-0529") -> 801-505-0529 | J6: =IFERROR(__xludf.DUMMYFUNCTION("""COMPUTED_VALUE"""),"40.72037806604348, -111.95827946249824") -> 40.72037806604348, -111.95827946249824 | K6: =IFERROR(__xludf.DUMMYFUNCTION("""COMPUTED_VALUE"""),"{""regular"":[{""days"":[""Mo"",""Tu"",""We"",""Th"",""Fr""],""open"":null,""close"":null}]}") -> {"regular":[{"days":["Mo","Tu","We","Th","Fr"],"open":null,"close":null}]} | L6: =IFERROR(__xludf.DUMMYFUNCTION("""COMPUTED_VALUE"""),"Apply online") -> Apply online | M6: =IFERROR(__xludf.DUMMYFUNCTION("""COMPUTED_VALUE"""),31.0) -> 31 | N6: =IFERROR(__xludf.DUMMYFUNCTION("""COMPUTED_VALUE"""),"Medical - Primary Care") -> Medical - Primary Care | O6: =IFERROR(__xludf.DUMMYFUNCTION("""COMPUTED_VALUE"""),1.0) -> 1 | P6: =IFERROR(__xludf.DUMMYFUNCTION("""COMPUTED_VALUE"""),"ACTIVE") -> ACTIVE | Q6: =IFERROR(__xludf.DUMMYFUNCTION("""COMPUTED_VALUE"""),46045.0) -> 46045 | R6: =IFERROR(__xludf.DUMMYFUNCTION("""COMPUTED_VALUE"""),"Verified online") -> Verified online | S6: =IFERROR(__xludf.DUMMYFUNCTION("""COMPUTED_VALUE"""),"Provides mobility equipment at a low cost fee. Equipment is customized for the needs of the individual. They do not provide medical supplies or financial assistance. Requests should be submitted online by a physical therapist if you have one, otherwise co"&"ntact the organization directly thru their website. ") -> Provides mobility equipment at a low cost fee. Equipment is customized for the needs of the individual. They do not provide medical supplies or financial assistance. Requests should be submitted online by a physical therapist if you have one, otherwise contact the organization directly thru their website. | T6: =IFERROR(__xludf.DUMMYFUNCTION("""COMPUTED_VALUE"""),FALSE) -> FALSE | U6: =IFERROR(__xludf.DUMMYFUNCTION("""COMPUTED_VALUE"""),FALSE) -> FALSE | V6: =IFERROR(__xludf.DUMMYFUNCTION("""COMPUTED_VALUE"""),"https://abilityfound.org/pages/need-help") -> https://abilityfound.org/pages/need-help | W6: =IFERROR(__xludf.DUMMYFUNCTION("""COMPUTED_VALUE"""),"https://www.google.com/maps/place/Ability+Found+Charity/@40.7202562,-111.9631665,17z/data=!3m1!4b1!4m6!3m5!1s0x87528a2b55962c8f:0x4d686ad30de1f05d!8m2!3d40.7202563!4d-111.9582902!16s%2Fg%2F1vzv443n?entry=ttu&g_ep=EgoyMDI2MDEyMC4wIKXMDSoKLDEwMDc5MjA2OUgBUA"&"M%3D") -> https://www.google.com/maps/place/Ability+Found+Charity/@40.7202562,-111.9631665,17z/data=!3m1!4b1!4m6!3m5!1s0x87528a2b55962c8f:0x4d686ad30de1f05d!8m2!3d40.7202563!4d-111.9582902!16s%2Fg%2F1vzv443n?entry=ttu&g_ep=EgoyMDI2MDEyMC4wIKXMDSoKLDEwMDc5MjA2OUgBUAM%3D | Y6: =IFERROR(__xludf.DUMMYFUNCTION("""COMPUTED_VALUE"""),"West Valley City") -> West Valley City | Z6: =IFERROR(__xludf.DUMMYFUNCTION("""COMPUTED_VALUE"""),"West Valley City") -> West Valley City | AA6: =IFERROR(__xludf.DUMMYFUNCTION("""COMPUTED_VALUE"""),"Ability Found") -> Ability Found | AB6: =IFERROR(__xludf.DUMMYFUNCTION("""COMPUTED_VALUE"""),"West Valley City") -> West Valley City
A7: 6 | B7: =IFERROR(__xludf.DUMMYFUNCTION("""COMPUTED_VALUE"""),"[""77418"", ""77452"", ""77474""]") -> ["77418", "77452", "77474"] | C7: =IFERROR(__xludf.DUMMYFUNCTION("""COMPUTED_VALUE"""),"AccessHealth Bellville WIC Center") -> AccessHealth Bellville WIC Center | D7: =IFERROR(__xludf.DUMMYFUNCTION("""COMPUTED_VALUE"""),"800 E Wendt Street") -> 800 E Wendt Street | F7: =IFERROR(__xludf.DUMMYFUNCTION("""COMPUTED_VALUE"""),"Bellville") -> Bellville | G7: =IFERROR(__xludf.DUMMYFUNCTION("""COMPUTED_VALUE"""),"TX") -> TX | H7: =IFERROR(__xludf.DUMMYFUNCTION("""COMPUTED_VALUE"""),"77418") -> 77418 | I7: =IFERROR(__xludf.DUMMYFUNCTION("""COMPUTED_VALUE"""),"979-865-9140") -> 979-865-9140 | J7: =IFERROR(__xludf.DUMMYFUNCTION("""COMPUTED_VALUE"""),"29.9396576157338, -96.2537193375798") -> 29.9396576157338, -96.2537193375798 | K7: =IFERROR(__xludf.DUMMYFUNCTION("""COMPUTED_VALUE"""),"{""regular"":[{""days"":[""Mo"",""Tu"",""Th""],""open"":""08:00"",""close"":""17:30""}]}") -> {"regular":[{"days":["Mo","Tu","Th"],"open":"08:00","close":"17:30"}]} | M7: =IFERROR(__xludf.DUMMYFUNCTION("""COMPUTED_VALUE"""),44.0) -> 44 | N7: =IFERROR(__xludf.DUMMYFUNCTION("""COMPUTED_VALUE"""),"Mother & Child") -> Mother & Child | O7: =IFERROR(__xludf.DUMMYFUNCTION("""COMPUTED_VALUE"""),1.0) -> 1 | P7: =IFERROR(__xludf.DUMMYFUNCTION("""COMPUTED_VALUE"""),"ACTIVE") -> ACTIVE | Q7: =IFERROR(__xludf.DUMMYFUNCTION("""COMPUTED_VALUE"""),45831.0) -> 45831 | R7: =IFERROR(__xludf.DUMMYFUNCTION("""COMPUTED_VALUE"""),"Verified online") -> Verified online | S7: =IFERROR(__xludf.DUMMYFUNCTION("""COMPUTED_VALUE"""),"WIC is a special supplemental nutrition program for women, infants and children. It is a nutrition program for pregnant, breastfeeding women and families with children younger than 5 years old. To qualify you must meet income guidelines but if you receiv"&"e Medicaid, SNAP or TANF, then you already meet the income eligibility guidelines for WIC. AccessHealth is a private, not-for-profit organization and a Federally Qualified Health Center. It's primary focus is the low-income population of Fort Bend and Wa"&"ller counties but will not turn anyone away, regardless of income or circumstance. Fee based group sessions for Family Violence Intervention and Prevention and Anger Management Programs. ") -> WIC is a special supplemental nutrition program for women, infants and children. It is a nutrition program for pregnant, breastfeeding women and families with children younger than 5 years old. To qualify you must meet income guidelines but if you receive Medicaid, SNAP or TANF, then you already meet the income eligibility guidelines for WIC. AccessHealth is a private, not-for-profit organization and a Federally Qualified Health Center. It's primary focus is the low-income population of Fort Bend and Waller counties but will not turn anyone away, regardless of income or circumstance. Fee based group sessions for Family Violence Intervention and Prevention and Anger Management Programs. | T7: =IFERROR(__xludf.DUMMYFUNCTION("""COMPUTED_VALUE"""),FALSE) -> FALSE | U7: =IFERROR(__xludf.DUMMYFUNCTION("""COMPUTED_VALUE"""),FALSE) -> FALSE | V7: =IFERROR(__xludf.DUMMYFUNCTION("""COMPUTED_VALUE"""),"https://www.myaccesshealth.org/") -> https://www.myaccesshealth.org/ | W7: =IFERROR(__xludf.DUMMYFUNCTION("""COMPUTED_VALUE"""),"https://www.google.com/maps/place/Access+Health+Bellville+WIC+Clinic/@29.9400956,-96.2564832,16z/data=!3m1!4b1!4m6!3m5!1s0x86415214a20f7165:0x9a29241743df954d!8m2!3d29.940091!4d-96.2539029!16s%2Fg%2F11bzsdntr2?entry=ttu&g_ep=EgoyMDI1MDYxNy4wIKXMDSoASAFQAw"&"%3D%3D") -> https://www.google.com/maps/place/Access+Health+Bellville+WIC+Clinic/@29.9400956,-96.2564832,16z/data=!3m1!4b1!4m6!3m5!1s0x86415214a20f7165:0x9a29241743df954d!8m2!3d29.940091!4d-96.2539029!16s%2Fg%2F11bzsdntr2?entry=ttu&g_ep=EgoyMDI1MDYxNy4wIKXMDSoASAFQAw%3D%3D | Y7: =IFERROR(__xludf.DUMMYFUNCTION("""COMPUTED_VALUE"""),"Bellville") -> Bellville | Z7: =IFERROR(__xludf.DUMMYFUNCTION("""COMPUTED_VALUE"""),"Bellville") -> Bellville | AA7: =IFERROR(__xludf.DUMMYFUNCTION("""COMPUTED_VALUE"""),"AccessHealth") -> AccessHealth | AB7: =IFERROR(__xludf.DUMMYFUNCTION("""COMPUTED_VALUE"""),"Bellville") -> Bellville
A8: 7 | B8: =IFERROR(__xludf.DUMMYFUNCTION("""COMPUTED_VALUE"""),"[""77053"", ""77406"", ""77407"", ""77417"", ""77423"", ""77430"", ""77441"", ""77444"", ""77451"", ""77459"", ""77461"", ""77464"", ""77469"", ""77471"", ""77476"", ""77477"", ""77478"", ""77479"", ""77481"", ""77485"", ""77489"", ""77494"", ""77498"", "&"""77545"", ""77583"", ""77584""]") -> ["77053", "77406", "77407", "77417", "77423", "77430", "77441", "77444", "77451", "77459", "77461", "77464", "77469", "77471", "77476", "77477", "77478", "77479", "77481", "77485", "77489", "77494", "77498", "77545", "77583", "77584"] | C8: =IFERROR(__xludf.DUMMYFUNCTION("""COMPUTED_VALUE"""),"AccessHealth Brookshire Clinic") -> AccessHealth Brookshire Clinic | D8: =IFERROR(__xludf.DUMMYFUNCTION("""COMPUTED_VALUE"""),"533 FM 359 S") -> 533 FM 359 S | F8: =IFERROR(__xludf.DUMMYFUNCTION("""COMPUTED_VALUE"""),"Brookshire") -> Brookshire | G8: =IFERROR(__xludf.DUMMYFUNCTION("""COMPUTED_VALUE"""),"TX") -> TX | H8: =IFERROR(__xludf.DUMMYFUNCTION("""COMPUTED_VALUE"""),"77423") -> 77423 | I8: =IFERROR(__xludf.DUMMYFUNCTION("""COMPUTED_VALUE"""),"281-342-4530") -> 281-342-4530 | J8: =IFERROR(__xludf.DUMMYFUNCTION("""COMPUTED_VALUE"""),"29.77434, -95.950801") -> 29.77434, -95.950801 | K8: =IFERROR(__xludf.DUMMYFUNCTION("""COMPUTED_VALUE"""),"{""regular"":[{""days"":[""Mo"",""Tu"",""We""],""open"":""07:00"",""close"":""17:30""},{""days"":[""Th"",""Fr""],""open"":""08:00"",""close"":""17:00""}]}") -> {"regular":[{"days":["Mo","Tu","We"],"open":"07:00","close":"17:30"},{"days":["Th","Fr"],"open":"08:00","close":"17:00"}]} | M8: =IFERROR(__xludf.DUMMYFUNCTION("""COMPUTED_VALUE"""),31.0) -> 31 | N8: =IFERROR(__xludf.DUMMYFUNCTION("""COMPUTED_VALUE"""),"Medical - Primary Care") -> Medical - Primary Care | O8: =IFERROR(__xludf.DUMMYFUNCTION("""COMPUTED_VALUE"""),1.0) -> 1 | P8: =IFERROR(__xludf.DUMMYFUNCTION("""COMPUTED_VALUE"""),"ACTIVE") -> ACTIVE | Q8: =IFERROR(__xludf.DUMMYFUNCTION("""COMPUTED_VALUE"""),45831.0) -> 45831 | R8: =IFERROR(__xludf.DUMMYFUNCTION("""COMPUTED_VALUE"""),"Verified online") -> Verified online | S8: =IFERROR(__xludf.DUMMYFUNCTION("""COMPUTED_VALUE"""),"Family medicine, primary care, adults, women's health, pediatric, counseling and mental health, pharmacy, immunizations, Lab, OB.GYN, Hepatitis testing and treatment, substance abuse and addiction. AccessHealth is a private, not-for-profit organization an"&"d a Federally Qualified Health Center. It's primary focus is the low-income population of Fort Bend and Waller counties but will not turn anyone away, regardless of income or circumstance. Sliding scale of fee based on income.") -> Family medicine, primary care, adults, women's health, pediatric, counseling and mental health, pharmacy, immunizations, Lab, OB.GYN, Hepatitis testing and treatment, substance abuse and addiction. AccessHealth is a private, not-for-profit organization and a Federally Qualified Health Center. It's primary focus is the low-income population of Fort Bend and Waller counties but will not turn anyone away, regardless of income or circumstance. Sliding scale of fee based on income. | T8: =IFERROR(__xludf.DUMMYFUNCTION("""COMPUTED_VALUE"""),FALSE) -> FALSE | U8: =IFERROR(__xludf.DUMMYFUNCTION("""COMPUTED_VALUE"""),FALSE) -> FALSE | V8: =IFERROR(__xludf.DUMMYFUNCTION("""COMPUTED_VALUE"""),"https://www.myaccesshealth.org/") -> https://www.myaccesshealth.org/ | W8: =IFERROR(__xludf.DUMMYFUNCTION("""COMPUTED_VALUE"""),"https://www.google.com/maps/place/AccessHealth+Brookshire+Clinic/@29.774261,-95.9528807,17z/data=!3m1!4b1!4m6!3m5!1s0x86413ba32ec6aa43:0xecb591ea00b3e4b5!8m2!3d29.7742564!4d-95.9503004!16s%2Fg%2F11hc_k0k4f?entry=ttu&g_ep=EgoyMDI1MDYxNy4wIKXMDSoASAFQAw%3D%"&"3D") -> https://www.google.com/maps/place/AccessHealth+Brookshire+Clinic/@29.774261,-95.9528807,17z/data=!3m1!4b1!4m6!3m5!1s0x86413ba32ec6aa43:0xecb591ea00b3e4b5!8m2!3d29.7742564!4d-95.9503004!16s%2Fg%2F11hc_k0k4f?entry=ttu&g_ep=EgoyMDI1MDYxNy4wIKXMDSoASAFQAw%3D%3D | Y8: =IFERROR(__xludf.DUMMYFUNCTION("""COMPUTED_VALUE"""),"Brookshire") -> Brookshire | Z8: =IFERROR(__xludf.DUMMYFUNCTION("""COMPUTED_VALUE"""),"Brookshire") -> Brookshire | AA8: =IFERROR(__xludf.DUMMYFUNCTION("""COMPUTED_VALUE"""),"AccessHealth") -> AccessHealth | AB8: =IFERROR(__xludf.DUMMYFUNCTION("""COMPUTED_VALUE"""),"Brookshire") -> Brookshire
A9: 8 | B9: =IFERROR(__xludf.DUMMYFUNCTION("""COMPUTED_VALUE"""),"[""77053"", ""77406"", ""77407"", ""77417"", ""77423"", ""77430"", ""77441"", ""77444"", ""77451"", ""77459"", ""77461"", ""77464"", ""77469"", ""77471"", ""77476"", ""77477"", ""77478"", ""77479"", ""77481"", ""77485"", ""77489"", ""77494"", ""77498"", "&"""77545"", ""77583"", ""77584""]") -> ["77053", "77406", "77407", "77417", "77423", "77430", "77441", "77444", "77451", "77459", "77461", "77464", "77469", "77471", "77476", "77477", "77478", "77479", "77481", "77485", "77489", "77494", "77498", "77545", "77583", "77584"] | C9: =IFERROR(__xludf.DUMMYFUNCTION("""COMPUTED_VALUE"""),"AccessHealth Brookshire WIC Center") -> AccessHealth Brookshire WIC Center | D9: =IFERROR(__xludf.DUMMYFUNCTION("""COMPUTED_VALUE"""),"531 FM 359 S") -> 531 FM 359 S | F9: =IFERROR(__xludf.DUMMYFUNCTION("""COMPUTED_VALUE"""),"Brookshire") -> Brookshire | G9: =IFERROR(__xludf.DUMMYFUNCTION("""COMPUTED_VALUE"""),"TX") -> TX | H9: =IFERROR(__xludf.DUMMYFUNCTION("""COMPUTED_VALUE"""),"77423") -> 77423 | I9: =IFERROR(__xludf.DUMMYFUNCTION("""COMPUTED_VALUE"""),"281-822-4242") -> 281-822-4242 | J9: =IFERROR(__xludf.DUMMYFUNCTION("""COMPUTED_VALUE"""),"29.774335, -95.951041") -> 29.774335, -95.951041 | K9: =IFERROR(__xludf.DUMMYFUNCTION("""COMPUTED_VALUE"""),"{""regular"":[{""days"":[""Mo"",""We"",""Th""],""open"":""08:00"",""close"":""17:30""},{""days"":[""Tu""],""open"":""08:00"",""close"":""18:00""},{""days"":[""Fr""],""open"":""08:00"",""close"":""13:30""}]}") -> {"regular":[{"days":["Mo","We","Th"],"open":"08:00","close":"17:30"},{"days":["Tu"],"open":"08:00","close":"18:00"},{"days":["Fr"],"open":"08:00","close":"13:30"}]} | M9: =IFERROR(__xludf.DUMMYFUNCTION("""COMPUTED_VALUE"""),44.0) -> 44 | N9: =IFERROR(__xludf.DUMMYFUNCTION("""COMPUTED_VALUE"""),"Mother & Child") -> Mother & Child | O9: =IFERROR(__xludf.DUMMYFUNCTION("""COMPUTED_VALUE"""),1.0) -> 1 | P9: =IFERROR(__xludf.DUMMYFUNCTION("""COMPUTED_VALUE"""),"ACTIVE") -> ACTIVE | Q9: =IFERROR(__xludf.DUMMYFUNCTION("""COMPUTED_VALUE"""),45831.0) -> 45831 | R9: =IFERROR(__xludf.DUMMYFUNCTION("""COMPUTED_VALUE"""),"Verified online") -> Verified online | S9: =IFERROR(__xludf.DUMMYFUNCTION("""COMPUTED_VALUE"""),"WIC is a special supplemental nutrition program for women, infants and children. It is a nutrition program for pregnant, breastfeeding women and families with children younger than 5 years old. To qualify you must meet income guidelines but if you receiv"&"e Medicaid, SNAP or TANF, then you already meet the income eligibility guidelines for WIC. AccessHealth is a private, not-for-profit organization and a Federally Qualified Health Center. It's primary focus is the low-income population of Fort Bend and Wa"&"ller counties but will not turn anyone away, regardless of income or circumstance. ") -> WIC is a special supplemental nutrition program for women, infants and children. It is a nutrition program for pregnant, breastfeeding women and families with children younger than 5 years old. To qualify you must meet income guidelines but if you receive Medicaid, SNAP or TANF, then you already meet the income eligibility guidelines for WIC. AccessHealth is a private, not-for-profit organization and a Federally Qualified Health Center. It's primary focus is the low-income population of Fort Bend and Waller counties but will not turn anyone away, regardless of income or circumstance. | T9: =IFERROR(__xludf.DUMMYFUNCTION("""COMPUTED_VALUE"""),FALSE) -> FALSE | U9: =IFERROR(__xludf.DUMMYFUNCTION("""COMPUTED_VALUE"""),FALSE) -> FALSE | V9: =IFERROR(__xludf.DUMMYFUNCTION("""COMPUTED_VALUE"""),"https://www.myaccesshealth.org/") -> https://www.myaccesshealth.org/ | W9: =IFERROR(__xludf.DUMMYFUNCTION("""COMPUTED_VALUE"""),"https://www.google.com/maps/place/Access+Health+Brookshire+WIC+Clinic/@29.7743128,-95.9532197,17z/data=!3m1!4b1!4m6!3m5!1s0x86413ba32420529b:0x5798dda56f02582e!8m2!3d29.7743082!4d-95.9506394!16s%2Fg%2F11hcd_dmqz?entry=ttu&g_ep=EgoyMDI1MDYxNy4wIKXMDSoASAFQ"&"Aw%3D%3D") -> https://www.google.com/maps/place/Access+Health+Brookshire+WIC+Clinic/@29.7743128,-95.9532197,17z/data=!3m1!4b1!4m6!3m5!1s0x86413ba32420529b:0x5798dda56f02582e!8m2!3d29.7743082!4d-95.9506394!16s%2Fg%2F11hcd_dmqz?entry=ttu&g_ep=EgoyMDI1MDYxNy4wIKXMDSoASAFQAw%3D%3D | Y9: =IFERROR(__xludf.DUMMYFUNCTION("""COMPUTED_VALUE"""),"Brookshire") -> Brookshire | Z9: =IFERROR(__xludf.DUMMYFUNCTION("""COMPUTED_VALUE"""),"Brookshire") -> Brookshire | AA9: =IFERROR(__xludf.DUMMYFUNCTION("""COMPUTED_VALUE"""),"AccessHealth") -> AccessHealth | AB9: =IFERROR(__xludf.DUMMYFUNCTION("""COMPUTED_VALUE"""),"Brookshire") -> Brookshire
A10: 9 | B10: =IFERROR(__xludf.DUMMYFUNCTION("""COMPUTED_VALUE"""),"[""77053"", ""77406"", ""77407"", ""77417"", ""77423"", ""77430"", ""77441"", ""77444"", ""77451"", ""77459"", ""77461"", ""77464"", ""77469"", ""77471"", ""77476"", ""77477"", ""77478"", ""77479"", ""77481"", ""77485"", ""77489"", ""77494"", ""77498"", "&"""77545"", ""77583"", ""77584""]") -> ["77053", "77406", "77407", "77417", "77423", "77430", "77441", "77444", "77451", "77459", "77461", "77464", "77469", "77471", "77476", "77477", "77478", "77479", "77481", "77485", "77489", "77494", "77498", "77545", "77583", "77584"] | C10: =IFERROR(__xludf.DUMMYFUNCTION("""COMPUTED_VALUE"""),"AccessHealth East Fort Bend Clinic") -> AccessHealth East Fort Bend Clinic | D10: =IFERROR(__xludf.DUMMYFUNCTION("""COMPUTED_VALUE"""),"7707 Highway 6 South") -> 7707 Highway 6 South | F10: =IFERROR(__xludf.DUMMYFUNCTION("""COMPUTED_VALUE"""),"Missouri City") -> Missouri City | G10: =IFERROR(__xludf.DUMMYFUNCTION("""COMPUTED_VALUE"""),"TX") -> TX | H10: =IFERROR(__xludf.DUMMYFUNCTION("""COMPUTED_VALUE"""),"77459") -> 77459 | I10: =IFERROR(__xludf.DUMMYFUNCTION("""COMPUTED_VALUE"""),"281-342-4530") -> 281-342-4530 | J10: =IFERROR(__xludf.DUMMYFUNCTION("""COMPUTED_VALUE"""),"29.55004371572688, -95.54838500791375") -> 29.55004371572688, -95.54838500791375 | K10: =IFERROR(__xludf.DUMMYFUNCTION("""COMPUTED_VALUE"""),"{""regular"":[{""days"":[""Mo"",""Tu"",""We"",""Th""],""open"":""08:00"",""close"":""17:00""}]}") -> {"regular":[{"days":["Mo","Tu","We","Th"],"open":"08:00","close":"17:00"}]} | M10: =IFERROR(__xludf.DUMMYFUNCTION("""COMPUTED_VALUE"""),31.0) -> 31 | N10: =IFERROR(__xludf.DUMMYFUNCTION("""COMPUTED_VALUE"""),"Medical - Primary Care") -> Medical - Primary Care | O10: =IFERROR(__xludf.DUMMYFUNCTION("""COMPUTED_VALUE"""),1.0) -> 1 | P10: =IFERROR(__xludf.DUMMYFUNCTION("""COMPUTED_VALUE"""),"ACTIVE") -> ACTIVE | Q10: =IFERROR(__xludf.DUMMYFUNCTION("""COMPUTED_VALUE"""),45831.0) -> 45831 | R10: =IFERROR(__xludf.DUMMYFUNCTION("""COMPUTED_VALUE"""),"Verified online") -> Verified online | S10: =IFERROR(__xludf.DUMMYFUNCTION("""COMPUTED_VALUE"""),"Family medicine, primary care, adults, women's health, pediatric, counseling and mental health, pharmacy, immunizations, Lab, OB.GYN, Hepatitis testing and treatment, substance abuse and addiction. AccessHealth is a private, not-for-profit organization an"&"d a Federally Qualified Health Center. It's primary focus is the low-income population of Fort Bend and Waller counties but will not turn anyone away, regardless of income or circumstance. Sliding scale of fee based on income.") -> Family medicine, primary care, adults, women's health, pediatric, counseling and mental health, pharmacy, immunizations, Lab, OB.GYN, Hepatitis testing and treatment, substance abuse and addiction. AccessHealth is a private, not-for-profit organization and a Federally Qualified Health Center. It's primary focus is the low-income population of Fort Bend and Waller counties but will not turn anyone away, regardless of income or circumstance. Sliding scale of fee based on income. | T10: =IFERROR(__xludf.DUMMYFUNCTION("""COMPUTED_VALUE"""),FALSE) -> FALSE | U10: =IFERROR(__xludf.DUMMYFUNCTION("""COMPUTED_VALUE"""),FALSE) -> FALSE | V10: =IFERROR(__xludf.DUMMYFUNCTION("""COMPUTED_VALUE"""),"https://www.myaccesshealth.org/") -> https://www.myaccesshealth.org/ | W10: =IFERROR(__xludf.DUMMYFUNCTION("""COMPUTED_VALUE"""),"https://www.google.com/maps/place/AccessHealth+East+Fort+Bend/@29.5498337,-95.5509975,17z/data=!3m1!4b1!4m6!3m5!1s0x8640ef623897ab5b:0x45df221a3b363090!8m2!3d29.5498291!4d-95.5484172!16s%2Fg%2F11g3zk_tqr?entry=ttu&g_ep=EgoyMDI1MDYxNy4wIKXMDSoASAFQAw%3D%3D") -> https://www.google.com/maps/place/AccessHealth+East+Fort+Bend/@29.5498337,-95.5509975,17z/data=!3m1!4b1!4m6!3m5!1s0x8640ef623897ab5b:0x45df221a3b363090!8m2!3d29.5498291!4d-95.5484172!16s%2Fg%2F11g3zk_tqr?entry=ttu&g_ep=EgoyMDI1MDYxNy4wIKXMDSoASAFQAw%3D%3D | Y10: =IFERROR(__xludf.DUMMYFUNCTION("""COMPUTED_VALUE"""),"Missouri City") -> Missouri City | Z10: =IFERROR(__xludf.DUMMYFUNCTION("""COMPUTED_VALUE"""),"Missouri City, Plantation Park, Sienna") -> Missouri City, Plantation Park, Sienna | AA10: =IFERROR(__xludf.DUMMYFUNCTION("""COMPUTED_VALUE"""),"AccessHealth") -> AccessHealth | AB10: =IFERROR(__xludf.DUMMYFUNCTION("""COMPUTED_VALUE"""),"Missouri City") -> Missouri City
A11: 10 | B11: =IFERROR(__xludf.DUMMYFUNCTION("""COMPUTED_VALUE"""),"[""77445"", ""77446"", ""77466"", ""77492""]") -> ["77445", "77446", "77466", "77492"] | C11: =IFERROR(__xludf.DUMMYFUNCTION("""COMPUTED_VALUE"""),"AccessHealth Hempstead WIC Center") -> AccessHealth Hempstead WIC Center | D11: =IFERROR(__xludf.DUMMYFUNCTION("""COMPUTED_VALUE"""),"1737 13th Street") -> 1737 13th Street | F11: =IFERROR(__xludf.DUMMYFUNCTION("""COMPUTED_VALUE"""),"Hempstead") -> Hempstead | G11: =IFERROR(__xludf.DUMMYFUNCTION("""COMPUTED_VALUE"""),"TX") -> TX | H11: =IFERROR(__xludf.DUMMYFUNCTION("""COMPUTED_VALUE"""),"77445") -> 77445 | I11: =IFERROR(__xludf.DUMMYFUNCTION("""COMPUTED_VALUE"""),"979-557-2860") -> 979-557-2860 | J11: =IFERROR(__xludf.DUMMYFUNCTION("""COMPUTED_VALUE"""),"30.0888023601738, -96.0826334225169") -> 30.0888023601738, -96.0826334225169 | K11: =IFERROR(__xludf.DUMMYFUNCTION("""COMPUTED_VALUE"""),"{""regular"":[{""days"":[""Mo"",""Tu""],""open"":""08:00"",""close"":""18:00""},{""days"":[""We"",""Th""],""open"":""08:00"",""close"":""17:30""},{""days"":[""Fr""],""open"":""08:00"",""close"":""13:00""}]}") -> {"regular":[{"days":["Mo","Tu"],"open":"08:00","close":"18:00"},{"days":["We","Th"],"open":"08:00","close":"17:30"},{"days":["Fr"],"open":"08:00","close":"13:00"}]} | M11: =IFERROR(__xludf.DUMMYFUNCTION("""COMPUTED_VALUE"""),44.0) -> 44 | N11: =IFERROR(__xludf.DUMMYFUNCTION("""COMPUTED_VALUE"""),"Mother & Child") -> Mother & Child | O11: =IFERROR(__xludf.DUMMYFUNCTION("""COMPUTED_VALUE"""),1.0) -> 1 | P11: =IFERROR(__xludf.DUMMYFUNCTION("""COMPUTED_VALUE"""),"ACTIVE") -> ACTIVE | Q11: =IFERROR(__xludf.DUMMYFUNCTION("""COMPUTED_VALUE"""),45831.0) -> 45831 | R11: =IFERROR(__xludf.DUMMYFUNCTION("""COMPUTED_VALUE"""),"Verified online") -> Verified online | S11: =IFERROR(__xludf.DUMMYFUNCTION("""COMPUTED_VALUE"""),"WIC is a special supplemental nutrition program for women, infants and children. It is a nutrition program for pregnant, breastfeeding women and families with children younger than 5 years old. To qualify you must meet income guidelines but if you receiv"&"e Medicaid, SNAP or TANF, then you already meet the income eligibility guidelines for WIC. AccessHealth is a private, not-for-profit organization and a Federally Qualified Health Center. It's primary focus is the low-income population of Fort Bend and Wa"&"ller counties but will not turn anyone away, regardless of income or circumstance. ") -> WIC is a special supplemental nutrition program for women, infants and children. It is a nutrition program for pregnant, breastfeeding women and families with children younger than 5 years old. To qualify you must meet income guidelines but if you receive Medicaid, SNAP or TANF, then you already meet the income eligibility guidelines for WIC. AccessHealth is a private, not-for-profit organization and a Federally Qualified Health Center. It's primary focus is the low-income population of Fort Bend and Waller counties but will not turn anyone away, regardless of income or circumstance. | T11: =IFERROR(__xludf.DUMMYFUNCTION("""COMPUTED_VALUE"""),FALSE) -> FALSE | U11: =IFERROR(__xludf.DUMMYFUNCTION("""COMPUTED_VALUE"""),FALSE) -> FALSE | V11: =IFERROR(__xludf.DUMMYFUNCTION("""COMPUTED_VALUE"""),"https://www.myaccesshealth.org/") -> https://www.myaccesshealth.org/ | W11: =IFERROR(__xludf.DUMMYFUNCTION("""COMPUTED_VALUE"""),"https://www.google.com/maps/place/Access+Health+Hempstead+WIC+Clinic/@30.0885994,-96.0854671,17z/data=!3m1!4b1!4m6!3m5!1s0x8646cbf2bdd604ed:0x3871c5dc9c88752f!8m2!3d30.0885948!4d-96.0828868!16s%2Fg%2F11c80c5pwh?entry=ttu&g_ep=EgoyMDI1MDYxNy4wIKXMDSoASAFQA"&"w%3D%3D") -> https://www.google.com/maps/place/Access+Health+Hempstead+WIC+Clinic/@30.0885994,-96.0854671,17z/data=!3m1!4b1!4m6!3m5!1s0x8646cbf2bdd604ed:0x3871c5dc9c88752f!8m2!3d30.0885948!4d-96.0828868!16s%2Fg%2F11c80c5pwh?entry=ttu&g_ep=EgoyMDI1MDYxNy4wIKXMDSoASAFQAw%3D%3D | Y11: =IFERROR(__xludf.DUMMYFUNCTION("""COMPUTED_VALUE"""),"Hempstead") -> Hempstead | Z11: =IFERROR(__xludf.DUMMYFUNCTION("""COMPUTED_VALUE"""),"Hempstead, Northside") -> Hempstead, Northside | AA11: =IFERROR(__xludf.DUMMYFUNCTION("""COMPUTED_VALUE"""),"AccessHealth") -> AccessHealth | AB11: =IFERROR(__xludf.DUMMYFUNCTION("""COMPUTED_VALUE"""),"Hempstead") -> Hempstead
A12: 11 | B12: =IFERROR(__xludf.DUMMYFUNCTION("""COMPUTED_VALUE"""),"[""77053"", ""77406"", ""77407"", ""77417"", ""77423"", ""77430"", ""77441"", ""77444"", ""77451"", ""77459"", ""77461"", ""77464"", ""77469"", ""77471"", ""77476"", ""77477"", ""77478"", ""77479"", ""77481"", ""77485"", ""77489"", ""77494"", ""77498"", "&"""77545"", ""77583"", ""77584""]") -> ["77053", "77406", "77407", "77417", "77423", "77430", "77441", "77444", "77451", "77459", "77461", "77464", "77469", "77471", "77476", "77477", "77478", "77479", "77481", "77485", "77489", "77494", "77498", "77545", "77583", "77584"] | C12: =IFERROR(__xludf.DUMMYFUNCTION("""COMPUTED_VALUE"""),"AccessHealth Katy WIC Center") -> AccessHealth Katy WIC Center | D12: =IFERROR(__xludf.DUMMYFUNCTION("""COMPUTED_VALUE"""),"1260 Pin Oak Road") -> 1260 Pin Oak Road | E12: =IFERROR(__xludf.DUMMYFUNCTION("""COMPUTED_VALUE"""),"Suite 110") -> Suite 110 | F12: =IFERROR(__xludf.DUMMYFUNCTION("""COMPUTED_VALUE"""),"Katy") -> Katy | G12: =IFERROR(__xludf.DUMMYFUNCTION("""COMPUTED_VALUE"""),"TX") -> TX | H12: =IFERROR(__xludf.DUMMYFUNCTION("""COMPUTED_VALUE"""),"77494") -> 77494 | I12: =IFERROR(__xludf.DUMMYFUNCTION("""COMPUTED_VALUE"""),"281-391-4168") -> 281-391-4168 | J12: =IFERROR(__xludf.DUMMYFUNCTION("""COMPUTED_VALUE"""),"29.7721292, -95.8181261") -> 29.7721292, -95.8181261 | K12: =IFERROR(__xludf.DUMMYFUNCTION("""COMPUTED_VALUE"""),"{""regular"":[{""days"":[""Mo""],""open"":""08:00"",""close"":""19:00""},{""days"":[""Tu"",""We"",""Th""],""open"":""08:00"",""close"":""17:00""},{""days"":[""Fr""],""open"":""08:00"",""close"":""12:00""}]}") -> {"regular":[{"days":["Mo"],"open":"08:00","close":"19:00"},{"days":["Tu","We","Th"],"open":"08:00","close":"17:00"},{"days":["Fr"],"open":"08:00","close":"12:00"}]} | M12: =IFERROR(__xludf.DUMMYFUNCTION("""COMPUTED_VALUE"""),44.0) -> 44 | N12: =IFERROR(__xludf.DUMMYFUNCTION("""COMPUTED_VALUE"""),"Mother & Child") -> Mother & Child | O12: =IFERROR(__xludf.DUMMYFUNCTION("""COMPUTED_VALUE"""),1.0) -> 1 | P12: =IFERROR(__xludf.DUMMYFUNCTION("""COMPUTED_VALUE"""),"ACTIVE") -> ACTIVE | Q12: =IFERROR(__xludf.DUMMYFUNCTION("""COMPUTED_VALUE"""),45831.0) -> 45831 | R12: =IFERROR(__xludf.DUMMYFUNCTION("""COMPUTED_VALUE"""),"Verified online") -> Verified online | S12: =IFERROR(__xludf.DUMMYFUNCTION("""COMPUTED_VALUE"""),"WIC is a special supplemental nutrition program for women, infants and children. It is a nutrition program for pregnant, breastfeeding women and families with children younger than 5 years old. To qualify you must meet income guidelines but if you receiv"&"e Medicaid, SNAP or TANF, then you already meet the income eligibility guidelines for WIC. AccessHealth is a private, not-for-profit organization and a Federally Qualified Health Center. It's primary focus is the low-income population of Fort Bend and Wa"&"ller counties but will not turn anyone away, regardless of income or circumstance. ") -> WIC is a special supplemental nutrition program for women, infants and children. It is a nutrition program for pregnant, breastfeeding women and families with children younger than 5 years old. To qualify you must meet income guidelines but if you receive Medicaid, SNAP or TANF, then you already meet the income eligibility guidelines for WIC. AccessHealth is a private, not-for-profit organization and a Federally Qualified Health Center. It's primary focus is the low-income population of Fort Bend and Waller counties but will not turn anyone away, regardless of income or circumstance. | T12: =IFERROR(__xludf.DUMMYFUNCTION("""COMPUTED_VALUE"""),FALSE) -> FALSE | U12: =IFERROR(__xludf.DUMMYFUNCTION("""COMPUTED_VALUE"""),FALSE) -> FALSE | V12: =IFERROR(__xludf.DUMMYFUNCTION("""COMPUTED_VALUE"""),"https://www.myaccesshealth.org/") -> https://www.myaccesshealth.org/ | W12: =IFERROR(__xludf.DUMMYFUNCTION("""COMPUTED_VALUE"""),"https://www.google.com/maps/place/Access+Health+Katy+WIC+Clinic/@29.7715667,-95.8211363,17z/data=!3m2!4b1!5s0x8641241ea38f160d:0x1f5667d0be90dcb3!4m6!3m5!1s0x8641241ea41aa14b:0xbfb6bd3112b944c4!8m2!3d29.7715621!4d-95.818556!16s%2Fg%2F1tkb5hd8?entry=ttu&g_"&"ep=EgoyMDI1MDYxNy4wIKXMDSoASAFQAw%3D%3D") -> https://www.google.com/maps/place/Access+Health+Katy+WIC+Clinic/@29.7715667,-95.8211363,17z/data=!3m2!4b1!5s0x8641241ea38f160d:0x1f5667d0be90dcb3!4m6!3m5!1s0x8641241ea41aa14b:0xbfb6bd3112b944c4!8m2!3d29.7715621!4d-95.818556!16s%2Fg%2F1tkb5hd8?entry=ttu&g_ep=EgoyMDI1MDYxNy4wIKXMDSoASAFQAw%3D%3D | Y12: =IFERROR(__xludf.DUMMYFUNCTION("""COMPUTED_VALUE"""),"Katy") -> Katy | Z12: =IFERROR(__xludf.DUMMYFUNCTION("""COMPUTED_VALUE"""),"Cinco Ranch West, Firethorne, Katy, Seven Meadows") -> Cinco Ranch West, Firethorne, Katy, Seven Meadows | AA12: =IFERROR(__xludf.DUMMYFUNCTION("""COMPUTED_VALUE"""),"AccessHealth") -> AccessHealth | AB12: =IFERROR(__xludf.DUMMYFUNCTION("""COMPUTED_VALUE"""),"Katy") -> Katy
A13: 12 | B13: =IFERROR(__xludf.DUMMYFUNCTION("""COMPUTED_VALUE"""),"[""77053"", ""77406"", ""77407"", ""77417"", ""77423"", ""77430"", ""77441"", ""77444"", ""77451"", ""77459"", ""77461"", ""77464"", ""77469"", ""77471"", ""77476"", ""77477"", ""77478"", ""77479"", ""77481"", ""77485"", ""77489"", ""77494"", ""77498"", "&"""77545"", ""77583"", ""77584""]") -> ["77053", "77406", "77407", "77417", "77423", "77430", "77441", "77444", "77451", "77459", "77461", "77464", "77469", "77471", "77476", "77477", "77478", "77479", "77481", "77485", "77489", "77494", "77498", "77545", "77583", "77584"] | C13: =IFERROR(__xludf.DUMMYFUNCTION("""COMPUTED_VALUE"""),"AccessHealth Missouri City Clinic") -> AccessHealth Missouri City Clinic | D13: =IFERROR(__xludf.DUMMYFUNCTION("""COMPUTED_VALUE"""),"307 Texas Parkway") -> 307 Texas Parkway | E13: =IFERROR(__xludf.DUMMYFUNCTION("""COMPUTED_VALUE"""),"Suite 100") -> Suite 100 | F13: =IFERROR(__xludf.DUMMYFUNCTION("""COMPUTED_VALUE"""),"Missouri City") -> Missouri City | G13: =IFERROR(__xludf.DUMMYFUNCTION("""COMPUTED_VALUE"""),"TX") -> TX | H13: =IFERROR(__xludf.DUMMYFUNCTION("""COMPUTED_VALUE"""),"77489") -> 77489 | I13: =IFERROR(__xludf.DUMMYFUNCTION("""COMPUTED_VALUE"""),"281-342-4530") -> 281-342-4530 | J13: =IFERROR(__xludf.DUMMYFUNCTION("""COMPUTED_VALUE"""),"29.6178774285714, -95.537035") -> 29.6178774285714, -95.537035 | K13: =IFERROR(__xludf.DUMMYFUNCTION("""COMPUTED_VALUE"""),"{""regular"":[{""days"":[""Mo"",""We"",""Th"",""Fr""],""open"":""07:00"",""close"":""17:00""},{""days"":[""Tu""],""open"":""07:00"",""close"":""18:00""}]}") -> {"regular":[{"days":["Mo","We","Th","Fr"],"open":"07:00","close":"17:00"},{"days":["Tu"],"open":"07:00","close":"18:00"}]} | M13: =IFERROR(__xludf.DUMMYFUNCTION("""COMPUTED_VALUE"""),31.0) -> 31 | N13: =IFERROR(__xludf.DUMMYFUNCTION("""COMPUTED_VALUE"""),"Medical - Primary Care") -> Medical - Primary Care | O13: =IFERROR(__xludf.DUMMYFUNCTION("""COMPUTED_VALUE"""),1.0) -> 1 | P13: =IFERROR(__xludf.DUMMYFUNCTION("""COMPUTED_VALUE"""),"ACTIVE") -> ACTIVE | Q13: =IFERROR(__xludf.DUMMYFUNCTION("""COMPUTED_VALUE"""),45831.0) -> 45831 | R13: =IFERROR(__xludf.DUMMYFUNCTION("""COMPUTED_VALUE"""),"Verified online") -> Verified online | S13: =IFERROR(__xludf.DUMMYFUNCTION("""COMPUTED_VALUE"""),"Family medicine, primary care, adults, women's health, pediatric, counseling and mental health, pharmacy, immunizations, Lab, OB.GYN, Hepatitis testing and treatment, substance abuse and addiction. AccessHealth is a private, not-for-profit organization an"&"d a Federally Qualified Health Center. It's primary focus is the low-income population of Fort Bend and Waller counties but will not turn anyone away, regardless of income or circumstance. Sliding scale of fee based on income.") -> Family medicine, primary care, adults, women's health, pediatric, counseling and mental health, pharmacy, immunizations, Lab, OB.GYN, Hepatitis testing and treatment, substance abuse and addiction. AccessHealth is a private, not-for-profit organization and a Federally Qualified Health Center. It's primary focus is the low-income population of Fort Bend and Waller counties but will not turn anyone away, regardless of income or circumstance. Sliding scale of fee based on income. | T13: =IFERROR(__xludf.DUMMYFUNCTION("""COMPUTED_VALUE"""),FALSE) -> FALSE | U13: =IFERROR(__xludf.DUMMYFUNCTION("""COMPUTED_VALUE"""),FALSE) -> FALSE | V13: =IFERROR(__xludf.DUMMYFUNCTION("""COMPUTED_VALUE"""),"https://www.myaccesshealth.org/") -> https://www.myaccesshealth.org/ | W13: =IFERROR(__xludf.DUMMYFUNCTION("""COMPUTED_VALUE"""),"https://www.google.com/maps/place/AccessHealth+Missouri+City+Clinic/@29.6175145,-95.5386005,17z/data=!3m1!4b1!4m6!3m5!1s0x8640e8f2465c6023:0xf54e0d695a0a28f2!8m2!3d29.6175099!4d-95.5360202!16s%2Fg%2F1v3lqbd7?entry=ttu&g_ep=EgoyMDI1MDYxNy4wIKXMDSoASAFQAw%3"&"D%3D") -> https://www.google.com/maps/place/AccessHealth+Missouri+City+Clinic/@29.6175145,-95.5386005,17z/data=!3m1!4b1!4m6!3m5!1s0x8640e8f2465c6023:0xf54e0d695a0a28f2!8m2!3d29.6175099!4d-95.5360202!16s%2Fg%2F1v3lqbd7?entry=ttu&g_ep=EgoyMDI1MDYxNy4wIKXMDSoASAFQAw%3D%3D | Y13: =IFERROR(__xludf.DUMMYFUNCTION("""COMPUTED_VALUE"""),"Missouri City") -> Missouri City | Z13: =IFERROR(__xludf.DUMMYFUNCTION("""COMPUTED_VALUE"""),"Missouri City, Olde Missouri City Market Place, Quail Green South, Quail Valley, Sta-mo Annex") -> Missouri City, Olde Missouri City Market Place, Quail Green South, Quail Valley, Sta-mo Annex | AA13: =IFERROR(__xludf.DUMMYFUNCTION("""COMPUTED_VALUE"""),"AccessHealth") -> AccessHealth | AB13: =IFERROR(__xludf.DUMMYFUNCTION("""COMPUTED_VALUE"""),"Olde Missouri City Market Place") -> Olde Missouri City Market Place
A14: 13 | B14: =IFERROR(__xludf.DUMMYFUNCTION("""COMPUTED_VALUE"""),"[""77053"", ""77406"", ""77407"", ""77417"", ""77423"", ""77430"", ""77441"", ""77444"", ""77451"", ""77459"", ""77461"", ""77464"", ""77469"", ""77471"", ""77476"", ""77477"", ""77478"", ""77479"", ""77481"", ""77485"", ""77489"", ""77494"", ""77498"", "&"""77545"", ""77583"", ""77584""]") -> ["77053", "77406", "77407", "77417", "77423", "77430", "77441", "77444", "77451", "77459", "77461", "77464", "77469", "77471", "77476", "77477", "77478", "77479", "77481", "77485", "77489", "77494", "77498", "77545", "77583", "77584"] | C14: =IFERROR(__xludf.DUMMYFUNCTION("""COMPUTED_VALUE"""),"AccessHealth Richmond Clinic") -> AccessHealth Richmond Clinic | D14: =IFERROR(__xludf.DUMMYFUNCTION("""COMPUTED_VALUE"""),"400 Austin Street") -> 400 Austin Street | F14: =IFERROR(__xludf.DUMMYFUNCTION("""COMPUTED_VALUE"""),"Richmond") -> Richmond | G14: =IFERROR(__xludf.DUMMYFUNCTION("""COMPUTED_VALUE"""),"TX") -> TX | H14: =IFERROR(__xludf.DUMMYFUNCTION("""COMPUTED_VALUE"""),"77469") -> 77469 | I14: =IFERROR(__xludf.DUMMYFUNCTION("""COMPUTED_VALUE"""),"281-342-4530") -> 281-342-4530 | J14: =IFERROR(__xludf.DUMMYFUNCTION("""COMPUTED_VALUE"""),"29.578459, -95.759783") -> 29.578459, -95.759783 | K14: =IFERROR(__xludf.DUMMYFUNCTION("""COMPUTED_VALUE"""),"{""regular"":[{""days"":[""Mo"",""Tu"",""We"",""Th"",""Fr""],""open"":""07:00"",""close"":""17:00""},{""days"":[""Sa""],""open"":""08:00"",""close"":""12:00""}]}") -> {"regular":[{"days":["Mo","Tu","We","Th","Fr"],"open":"07:00","close":"17:00"},{"days":["Sa"],"open":"08:00","close":"12:00"}]} | M14: =IFERROR(__xludf.DUMMYFUNCTION("""COMPUTED_VALUE"""),31.0) -> 31 | N14: =IFERROR(__xludf.DUMMYFUNCTION("""COMPUTED_VALUE"""),"Medical - Primary Care") -> Medical - Primary Care | O14: =IFERROR(__xludf.DUMMYFUNCTION("""COMPUTED_VALUE"""),1.0) -> 1 | P14: =IFERROR(__xludf.DUMMYFUNCTION("""COMPUTED_VALUE"""),"ACTIVE") -> ACTIVE | Q14: =IFERROR(__xludf.DUMMYFUNCTION("""COMPUTED_VALUE"""),45831.0) -> 45831 | R14: =IFERROR(__xludf.DUMMYFUNCTION("""COMPUTED_VALUE"""),"Verified online") -> Verified online | S14: =IFERROR(__xludf.DUMMYFUNCTION("""COMPUTED_VALUE"""),"Family medicine, primary care, adults, women's health, pediatric, counseling and mental health, pharmacy, immunizations, Lab, OB.GYN, Hepatitis testing and treatment, substance abuse and addiction. AccessHealth is a private, not-for-profit organization an"&"d a Federally Qualified Health Center. It's primary focus is the low-income population of Fort Bend and Waller counties but will not turn anyone away, regardless of income or circumstance. Sliding scale of fee based on income.") -> Family medicine, primary care, adults, women's health, pediatric, counseling and mental health, pharmacy, immunizations, Lab, OB.GYN, Hepatitis testing and treatment, substance abuse and addiction. AccessHealth is a private, not-for-profit organization and a Federally Qualified Health Center. It's primary focus is the low-income population of Fort Bend and Waller counties but will not turn anyone away, regardless of income or circumstance. Sliding scale of fee based on income. | T14: =IFERROR(__xludf.DUMMYFUNCTION("""COMPUTED_VALUE"""),FALSE) -> FALSE | U14: =IFERROR(__xludf.DUMMYFUNCTION("""COMPUTED_VALUE"""),FALSE) -> FALSE | V14: =IFERROR(__xludf.DUMMYFUNCTION("""COMPUTED_VALUE"""),"https://www.myaccesshealth.org/") -> https://www.myaccesshealth.org/ | W14: =IFERROR(__xludf.DUMMYFUNCTION("""COMPUTED_VALUE"""),"https://www.google.com/maps/place/AccessHealth+Richmond+Clinic/@29.5786882,-95.7628537,17z/data=!3m1!4b1!4m6!3m5!1s0x86411e70c080105b:0x621ea27cba35c1c3!8m2!3d29.5786836!4d-95.7602734!16s%2Fg%2F1td72cvn?entry=ttu&g_ep=EgoyMDI1MDYxNy4wIKXMDSoASAFQAw%3D%3D") -> https://www.google.com/maps/place/AccessHealth+Richmond+Clinic/@29.5786882,-95.7628537,17z/data=!3m1!4b1!4m6!3m5!1s0x86411e70c080105b:0x621ea27cba35c1c3!8m2!3d29.5786836!4d-95.7602734!16s%2Fg%2F1td72cvn?entry=ttu&g_ep=EgoyMDI1MDYxNy4wIKXMDSoASAFQAw%3D%3D | Y14: =IFERROR(__xludf.DUMMYFUNCTION("""COMPUTED_VALUE"""),"Richmond") -> Richmond | Z14: =IFERROR(__xludf.DUMMYFUNCTION("""COMPUTED_VALUE"""),"Greatwood, Richmond") -> Greatwood, Richmond | AA14: =IFERROR(__xludf.DUMMYFUNCTION("""COMPUTED_VALUE"""),"AccessHealth") -> AccessHealth | AB14: =IFERROR(__xludf.DUMMYFUNCTION("""COMPUTED_VALUE"""),"Richmond") -> Richmond
